2018-02-07 15:55:04.693887: I tensorflow/core/platform/cpu_feature_guard.cc:137] Your CPU supports instructions that this TensorFlow binary was not compiled to use: SSE4.1 SSE4.2 AVX
------------------------------------------------------------------------
WARNING: libdeepspeech failed to load, resorting to deprecated code
         Refer to README.md for instructions on installing libdeepspeech
------------------------------------------------------------------------
WARNING:root:frame length (551) is greater than FFT size (512), frame will be truncated. Increase NFFT to avoid.
WARNING:root:frame length (551) is greater than FFT size (512), frame will be truncated. Increase NFFT to avoid.
WARNING:root:frame length (551) is greater than FFT size (512), frame will be truncated. Increase NFFT to avoid.
WARNING:root:frame length (551) is greater than FFT size (512), frame will be truncated. Increase NFFT to avoid.
WARNING:root:frame length (551) is greater than FFT size (512), frame will be truncated. Increase NFFT to avoid.
WARNING:root:frame length (551) is greater than FFT size (512), frame will be truncated. Increase NFFT to avoid.
WARNING:root:frame length (551) is greater than FFT size (512), frame will be truncated. Increase NFFT to avoid.
WARNING:root:frame length (551) is greater than FFT size (512), frame will be truncated. Increase NFFT to avoid.
WARNING:root:frame length (551) is greater than FFT size (512), frame will be truncated. Increase NFFT to avoid.
WARNING:root:frame length (551) is greater than FFT size (512), frame will be truncated. Increase NFFT to avoid.
WARNING:root:frame length (551) is greater than FFT size (512), frame will be truncated. Increase NFFT to avoid.
WARNING:root:frame length (551) is greater than FFT size (512), frame will be truncated. Increase NFFT to avoid.
WARNING:root:frame length (551) is greater than FFT size (512), frame will be truncated. Increase NFFT to avoid.
Loading the LM will be faster if you build a binary file.
Reading data/lm/pidgin.arpa
----5---10---15---20---25---30---35---40---45---50---55---60---65---70---75---80---85---90---95--100
****************************************************************************************************
2018-02-07 17:12:09.508985: I tensorflow/core/platform/cpu_feature_guard.cc:137] Your CPU supports instructions that this TensorFlow binary was not compiled to use: SSE4.1 SSE4.2 AVX
D Starting coordinator...
D Coordinator started.
E Assign requires shapes of both tensors to match. lhs shape= [494,29] rhs shape= [2048,29]
E 	 [[Node: save_1/Assign_44 = Assign[T=DT_FLOAT, _class=["loc:@h6"], use_locking=true, validate_shape=true, _device="/job:localhost/replica:0/task:0/device:CPU:0"](h6/Adam_1, save_1/RestoreV2_44)]]
E 
E Caused by op 'save_1/Assign_44', defined at:
E   File "./DeepSpeech.py", line 1862, in <module>
E     tf.app.run()
E   File "/home/john/anaconda3/lib/python3.5/site-packages/tensorflow/python/platform/app.py", line 48, in run
E     _sys.exit(main(_sys.argv[:1] + flags_passthrough))
E   File "./DeepSpeech.py", line 1819, in main
E     train()
E   File "./DeepSpeech.py", line 1588, in train
E     config=session_config) as session:
E   File "/home/john/anaconda3/lib/python3.5/site-packages/tensorflow/python/training/monitored_session.py", line 368, in MonitoredTrainingSession
E     stop_grace_period_secs=stop_grace_period_secs)
E   File "/home/john/anaconda3/lib/python3.5/site-packages/tensorflow/python/training/monitored_session.py", line 673, in __init__
E     stop_grace_period_secs=stop_grace_period_secs)
E   File "/home/john/anaconda3/lib/python3.5/site-packages/tensorflow/python/training/monitored_session.py", line 493, in __init__
E     self._sess = _RecoverableSession(self._coordinated_creator)
E   File "/home/john/anaconda3/lib/python3.5/site-packages/tensorflow/python/training/monitored_session.py", line 851, in __init__
E     _WrappedSession.__init__(self, self._create_session())
E   File "/home/john/anaconda3/lib/python3.5/site-packages/tensorflow/python/training/monitored_session.py", line 856, in _create_session
E     return self._sess_creator.create_session()
E   File "/home/john/anaconda3/lib/python3.5/site-packages/tensorflow/python/training/monitored_session.py", line 554, in create_session
E     self.tf_sess = self._session_creator.create_session()
E   File "/home/john/anaconda3/lib/python3.5/site-packages/tensorflow/python/training/monitored_session.py", line 419, in create_session
E     self._scaffold.finalize()
E   File "/home/john/anaconda3/lib/python3.5/site-packages/tensorflow/python/training/monitored_session.py", line 210, in finalize
E     self._saver = training_saver._get_saver_or_default()  # pylint: disable=protected-access
E   File "/home/john/anaconda3/lib/python3.5/site-packages/tensorflow/python/training/saver.py", line 807, in _get_saver_or_default
E     saver = Saver(sharded=True, allow_empty=True)
E   File "/home/john/anaconda3/lib/python3.5/site-packages/tensorflow/python/training/saver.py", line 1218, in __init__
E     self.build()
E   File "/home/john/anaconda3/lib/python3.5/site-packages/tensorflow/python/training/saver.py", line 1227, in build
E     self._build(self._filename, build_save=True, build_restore=True)
E   File "/home/john/anaconda3/lib/python3.5/site-packages/tensorflow/python/training/saver.py", line 1263, in _build
E     build_save=build_save, build_restore=build_restore)
E   File "/home/john/anaconda3/lib/python3.5/site-packages/tensorflow/python/training/saver.py", line 745, in _build_internal
E     restore_sequentially, reshape)
E   File "/home/john/anaconda3/lib/python3.5/site-packages/tensorflow/python/training/saver.py", line 470, in _AddShardedRestoreOps
E     name="restore_shard"))
E   File "/home/john/anaconda3/lib/python3.5/site-packages/tensorflow/python/training/saver.py", line 439, in _AddRestoreOps
E     assign_ops.append(saveable.restore(tensors, shapes))
E   File "/home/john/anaconda3/lib/python3.5/site-packages/tensorflow/python/training/saver.py", line 160, in restore
E     self.op.get_shape().is_fully_defined())
E   File "/home/john/anaconda3/lib/python3.5/site-packages/tensorflow/python/ops/state_ops.py", line 276, in assign
E     validate_shape=validate_shape)
E   File "/home/john/anaconda3/lib/python3.5/site-packages/tensorflow/python/ops/gen_state_ops.py", line 57, in assign
E     use_locking=use_locking, name=name)
E   File "/home/john/anaconda3/lib/python3.5/site-packages/tensorflow/python/framework/op_def_library.py", line 787, in _apply_op_helper
E     op_def=op_def)
E   File "/home/john/anaconda3/lib/python3.5/site-packages/tensorflow/python/framework/ops.py", line 2956, in create_op
E     op_def=op_def)
E   File "/home/john/anaconda3/lib/python3.5/site-packages/tensorflow/python/framework/ops.py", line 1470, in __init__
E     self._traceback = self._graph._extract_stack()  # pylint: disable=protected-access
E 
E InvalidArgumentError (see above for traceback): Assign requires shapes of both tensors to match. lhs shape= [494,29] rhs shape= [2048,29]
E 	 [[Node: save_1/Assign_44 = Assign[T=DT_FLOAT, _class=["loc:@h6"], use_locking=true, validate_shape=true, _device="/job:localhost/replica:0/task:0/device:CPU:0"](h6/Adam_1, save_1/RestoreV2_44)]]
E 
E The checkpoint in /home/john/.local/share/deepspeech/checkpoints does not match the shapes of the model. Did you change alphabet.txt or the --n_hidden parameter between train runs using the same checkpoint dir? Try moving or removing the contents of /home/john/.local/share/deepspeech/checkpoints.
2018-02-07 17:22:29.628444: I tensorflow/core/platform/cpu_feature_guard.cc:137] Your CPU supports instructions that this TensorFlow binary was not compiled to use: SSE4.1 SSE4.2 AVX
D Starting coordinator...
D Coordinator started.
Traceback (most recent call last):
  File "/home/john/anaconda3/lib/python3.5/site-packages/tensorflow/python/framework/importer.py", line 523, in import_graph_def
    ret.append(name_to_op[operation_name].outputs[output_index])
KeyError: 'b1'

During handling of the above exception, another exception occurred:

Traceback (most recent call last):
  File "./DeepSpeech.py", line 1862, in <module>
    tf.app.run()
  File "/home/john/anaconda3/lib/python3.5/site-packages/tensorflow/python/platform/app.py", line 48, in run
    _sys.exit(main(_sys.argv[:1] + flags_passthrough))
  File "./DeepSpeech.py", line 1819, in main
    train()
  File "./DeepSpeech.py", line 1565, in train
    var_tensors = tf.import_graph_def(graph_def, return_elements=var_names)
  File "/home/john/anaconda3/lib/python3.5/site-packages/tensorflow/python/framework/importer.py", line 526, in import_graph_def
    'Requested return_element %r not found in graph_def.' % name)
ValueError: Requested return_element 'b1:0' not found in graph_def.
2018-02-07 17:22:56.937596: I tensorflow/core/platform/cpu_feature_guard.cc:137] Your CPU supports instructions that this TensorFlow binary was not compiled to use: SSE4.1 SSE4.2 AVX
D Starting coordinator...
D Coordinator started.
Traceback (most recent call last):
  File "/home/john/anaconda3/lib/python3.5/site-packages/tensorflow/python/framework/importer.py", line 523, in import_graph_def
    ret.append(name_to_op[operation_name].outputs[output_index])
KeyError: 'b1'

During handling of the above exception, another exception occurred:

Traceback (most recent call last):
  File "./DeepSpeech.py", line 1862, in <module>
    tf.app.run()
  File "/home/john/anaconda3/lib/python3.5/site-packages/tensorflow/python/platform/app.py", line 48, in run
    _sys.exit(main(_sys.argv[:1] + flags_passthrough))
  File "./DeepSpeech.py", line 1819, in main
    train()
  File "./DeepSpeech.py", line 1565, in train
    var_tensors = tf.import_graph_def(graph_def, return_elements=var_names)
  File "/home/john/anaconda3/lib/python3.5/site-packages/tensorflow/python/framework/importer.py", line 526, in import_graph_def
    'Requested return_element %r not found in graph_def.' % name)
ValueError: Requested return_element 'b1:0' not found in graph_def.
2018-02-07 17:24:24.681097: I tensorflow/core/platform/cpu_feature_guard.cc:137] Your CPU supports instructions that this TensorFlow binary was not compiled to use: SSE4.1 SSE4.2 AVX
D Starting coordinator...
D Coordinator started.
E Assign requires shapes of both tensors to match. lhs shape= [494] rhs shape= [2048]
E 	 [[Node: save_1/Assign_1 = Assign[T=DT_FLOAT, _class=["loc:@b1"], use_locking=true, validate_shape=true, _device="/job:localhost/replica:0/task:0/device:CPU:0"](b1, save_1/RestoreV2_1)]]
E 
E Caused by op 'save_1/Assign_1', defined at:
E   File "./DeepSpeech.py", line 1862, in <module>
E     tf.app.run()
E   File "/home/john/anaconda3/lib/python3.5/site-packages/tensorflow/python/platform/app.py", line 48, in run
E     _sys.exit(main(_sys.argv[:1] + flags_passthrough))
E   File "./DeepSpeech.py", line 1819, in main
E     train()
E   File "./DeepSpeech.py", line 1588, in train
E     config=session_config) as session:
E   File "/home/john/anaconda3/lib/python3.5/site-packages/tensorflow/python/training/monitored_session.py", line 368, in MonitoredTrainingSession
E     stop_grace_period_secs=stop_grace_period_secs)
E   File "/home/john/anaconda3/lib/python3.5/site-packages/tensorflow/python/training/monitored_session.py", line 673, in __init__
E     stop_grace_period_secs=stop_grace_period_secs)
E   File "/home/john/anaconda3/lib/python3.5/site-packages/tensorflow/python/training/monitored_session.py", line 493, in __init__
E     self._sess = _RecoverableSession(self._coordinated_creator)
E   File "/home/john/anaconda3/lib/python3.5/site-packages/tensorflow/python/training/monitored_session.py", line 851, in __init__
E     _WrappedSession.__init__(self, self._create_session())
E   File "/home/john/anaconda3/lib/python3.5/site-packages/tensorflow/python/training/monitored_session.py", line 856, in _create_session
E     return self._sess_creator.create_session()
E   File "/home/john/anaconda3/lib/python3.5/site-packages/tensorflow/python/training/monitored_session.py", line 554, in create_session
E     self.tf_sess = self._session_creator.create_session()
E   File "/home/john/anaconda3/lib/python3.5/site-packages/tensorflow/python/training/monitored_session.py", line 419, in create_session
E     self._scaffold.finalize()
E   File "/home/john/anaconda3/lib/python3.5/site-packages/tensorflow/python/training/monitored_session.py", line 210, in finalize
E     self._saver = training_saver._get_saver_or_default()  # pylint: disable=protected-access
E   File "/home/john/anaconda3/lib/python3.5/site-packages/tensorflow/python/training/saver.py", line 807, in _get_saver_or_default
E     saver = Saver(sharded=True, allow_empty=True)
E   File "/home/john/anaconda3/lib/python3.5/site-packages/tensorflow/python/training/saver.py", line 1218, in __init__
E     self.build()
E   File "/home/john/anaconda3/lib/python3.5/site-packages/tensorflow/python/training/saver.py", line 1227, in build
E     self._build(self._filename, build_save=True, build_restore=True)
E   File "/home/john/anaconda3/lib/python3.5/site-packages/tensorflow/python/training/saver.py", line 1263, in _build
E     build_save=build_save, build_restore=build_restore)
E   File "/home/john/anaconda3/lib/python3.5/site-packages/tensorflow/python/training/saver.py", line 745, in _build_internal
E     restore_sequentially, reshape)
E   File "/home/john/anaconda3/lib/python3.5/site-packages/tensorflow/python/training/saver.py", line 470, in _AddShardedRestoreOps
E     name="restore_shard"))
E   File "/home/john/anaconda3/lib/python3.5/site-packages/tensorflow/python/training/saver.py", line 439, in _AddRestoreOps
E     assign_ops.append(saveable.restore(tensors, shapes))
E   File "/home/john/anaconda3/lib/python3.5/site-packages/tensorflow/python/training/saver.py", line 160, in restore
E     self.op.get_shape().is_fully_defined())
E   File "/home/john/anaconda3/lib/python3.5/site-packages/tensorflow/python/ops/state_ops.py", line 276, in assign
E     validate_shape=validate_shape)
E   File "/home/john/anaconda3/lib/python3.5/site-packages/tensorflow/python/ops/gen_state_ops.py", line 57, in assign
E     use_locking=use_locking, name=name)
E   File "/home/john/anaconda3/lib/python3.5/site-packages/tensorflow/python/framework/op_def_library.py", line 787, in _apply_op_helper
E     op_def=op_def)
E   File "/home/john/anaconda3/lib/python3.5/site-packages/tensorflow/python/framework/ops.py", line 2956, in create_op
E     op_def=op_def)
E   File "/home/john/anaconda3/lib/python3.5/site-packages/tensorflow/python/framework/ops.py", line 1470, in __init__
E     self._traceback = self._graph._extract_stack()  # pylint: disable=protected-access
E 
E InvalidArgumentError (see above for traceback): Assign requires shapes of both tensors to match. lhs shape= [494] rhs shape= [2048]
E 	 [[Node: save_1/Assign_1 = Assign[T=DT_FLOAT, _class=["loc:@b1"], use_locking=true, validate_shape=true, _device="/job:localhost/replica:0/task:0/device:CPU:0"](b1, save_1/RestoreV2_1)]]
E 
E The checkpoint in /home/john/.local/share/deepspeech/checkpoints does not match the shapes of the model. Did you change alphabet.txt or the --n_hidden parameter between train runs using the same checkpoint dir? Try moving or removing the contents of /home/john/.local/share/deepspeech/checkpoints.
2018-02-07 17:29:11.511185: I tensorflow/core/platform/cpu_feature_guard.cc:137] Your CPU supports instructions that this TensorFlow binary was not compiled to use: SSE4.1 SSE4.2 AVX
D Starting coordinator...
D Coordinator started.
E Assign requires shapes of both tensors to match. lhs shape= [494,29] rhs shape= [2048,29]
E 	 [[Node: save_1/Assign_44 = Assign[T=DT_FLOAT, _class=["loc:@h6"], use_locking=true, validate_shape=true, _device="/job:localhost/replica:0/task:0/device:CPU:0"](h6/Adam_1, save_1/RestoreV2_44)]]
E 
E Caused by op 'save_1/Assign_44', defined at:
E   File "./DeepSpeech.py", line 1862, in <module>
E     tf.app.run()
E   File "/home/john/anaconda3/lib/python3.5/site-packages/tensorflow/python/platform/app.py", line 48, in run
E     _sys.exit(main(_sys.argv[:1] + flags_passthrough))
E   File "./DeepSpeech.py", line 1819, in main
E     train()
E   File "./DeepSpeech.py", line 1588, in train
E     config=session_config) as session:
E   File "/home/john/anaconda3/lib/python3.5/site-packages/tensorflow/python/training/monitored_session.py", line 368, in MonitoredTrainingSession
E     stop_grace_period_secs=stop_grace_period_secs)
E   File "/home/john/anaconda3/lib/python3.5/site-packages/tensorflow/python/training/monitored_session.py", line 673, in __init__
E     stop_grace_period_secs=stop_grace_period_secs)
E   File "/home/john/anaconda3/lib/python3.5/site-packages/tensorflow/python/training/monitored_session.py", line 493, in __init__
E     self._sess = _RecoverableSession(self._coordinated_creator)
E   File "/home/john/anaconda3/lib/python3.5/site-packages/tensorflow/python/training/monitored_session.py", line 851, in __init__
E     _WrappedSession.__init__(self, self._create_session())
E   File "/home/john/anaconda3/lib/python3.5/site-packages/tensorflow/python/training/monitored_session.py", line 856, in _create_session
E     return self._sess_creator.create_session()
E   File "/home/john/anaconda3/lib/python3.5/site-packages/tensorflow/python/training/monitored_session.py", line 554, in create_session
E     self.tf_sess = self._session_creator.create_session()
E   File "/home/john/anaconda3/lib/python3.5/site-packages/tensorflow/python/training/monitored_session.py", line 419, in create_session
E     self._scaffold.finalize()
E   File "/home/john/anaconda3/lib/python3.5/site-packages/tensorflow/python/training/monitored_session.py", line 210, in finalize
E     self._saver = training_saver._get_saver_or_default()  # pylint: disable=protected-access
E   File "/home/john/anaconda3/lib/python3.5/site-packages/tensorflow/python/training/saver.py", line 807, in _get_saver_or_default
E     saver = Saver(sharded=True, allow_empty=True)
E   File "/home/john/anaconda3/lib/python3.5/site-packages/tensorflow/python/training/saver.py", line 1218, in __init__
E     self.build()
E   File "/home/john/anaconda3/lib/python3.5/site-packages/tensorflow/python/training/saver.py", line 1227, in build
E     self._build(self._filename, build_save=True, build_restore=True)
E   File "/home/john/anaconda3/lib/python3.5/site-packages/tensorflow/python/training/saver.py", line 1263, in _build
E     build_save=build_save, build_restore=build_restore)
E   File "/home/john/anaconda3/lib/python3.5/site-packages/tensorflow/python/training/saver.py", line 745, in _build_internal
E     restore_sequentially, reshape)
E   File "/home/john/anaconda3/lib/python3.5/site-packages/tensorflow/python/training/saver.py", line 470, in _AddShardedRestoreOps
E     name="restore_shard"))
E   File "/home/john/anaconda3/lib/python3.5/site-packages/tensorflow/python/training/saver.py", line 439, in _AddRestoreOps
E     assign_ops.append(saveable.restore(tensors, shapes))
E   File "/home/john/anaconda3/lib/python3.5/site-packages/tensorflow/python/training/saver.py", line 160, in restore
E     self.op.get_shape().is_fully_defined())
E   File "/home/john/anaconda3/lib/python3.5/site-packages/tensorflow/python/ops/state_ops.py", line 276, in assign
E     validate_shape=validate_shape)
E   File "/home/john/anaconda3/lib/python3.5/site-packages/tensorflow/python/ops/gen_state_ops.py", line 57, in assign
E     use_locking=use_locking, name=name)
E   File "/home/john/anaconda3/lib/python3.5/site-packages/tensorflow/python/framework/op_def_library.py", line 787, in _apply_op_helper
E     op_def=op_def)
E   File "/home/john/anaconda3/lib/python3.5/site-packages/tensorflow/python/framework/ops.py", line 2956, in create_op
E     op_def=op_def)
E   File "/home/john/anaconda3/lib/python3.5/site-packages/tensorflow/python/framework/ops.py", line 1470, in __init__
E     self._traceback = self._graph._extract_stack()  # pylint: disable=protected-access
E 
E InvalidArgumentError (see above for traceback): Assign requires shapes of both tensors to match. lhs shape= [494,29] rhs shape= [2048,29]
E 	 [[Node: save_1/Assign_44 = Assign[T=DT_FLOAT, _class=["loc:@h6"], use_locking=true, validate_shape=true, _device="/job:localhost/replica:0/task:0/device:CPU:0"](h6/Adam_1, save_1/RestoreV2_44)]]
E 
E The checkpoint in cp does not match the shapes of the model. Did you change alphabet.txt or the --n_hidden parameter between train runs using the same checkpoint dir? Try moving or removing the contents of cp.
2018-02-07 17:30:10.507550: I tensorflow/core/platform/cpu_feature_guard.cc:137] Your CPU supports instructions that this TensorFlow binary was not compiled to use: SSE4.1 SSE4.2 AVX
