2017-12-06 20:35:46.462710: I tensorflow/core/platform/cpu_feature_guard.cc:137] Your CPU supports instructions that this TensorFlow binary was not compiled to use: SSE4.1 SSE4.2 AVX
2017-12-06 20:35:47.475647: W tensorflow/core/framework/op_kernel.cc:1192] Out of range: Read less bytes than requested
/home/john/anaconda3/envs/tensorflow/lib/python3.6/importlib/_bootstrap.py:219: RuntimeWarning: compiletime version 3.5 of module 'tensorflow.python.framework.fast_tensor_util' does not match runtime version 3.6
  return f(*args, **kwds)
Traceback (most recent call last):
  File "/home/john/anaconda3/envs/tensorflow/lib/python3.6/site-packages/tensorflow/python/client/session.py", line 1323, in _do_call
    return fn(*args)
  File "/home/john/anaconda3/envs/tensorflow/lib/python3.6/site-packages/tensorflow/python/client/session.py", line 1302, in _run_fn
    status, run_metadata)
  File "/home/john/anaconda3/envs/tensorflow/lib/python3.6/site-packages/tensorflow/python/framework/errors_impl.py", line 473, in __exit__
    c_api.TF_GetCode(self.status.status))
tensorflow.python.framework.errors_impl.OutOfRangeError: Read less bytes than requested
	 [[Node: save/RestoreV2_43 = RestoreV2[dtypes=[DT_FLOAT], _device="/job:localhost/replica:0/task:0/device:CPU:0"](_arg_save/Const_0_0, save/RestoreV2_43/tensor_names, save/RestoreV2_43/shape_and_slices)]]

During handling of the above exception, another exception occurred:

Traceback (most recent call last):
  File "rnn_play.py", line 52, in <module>
    new_saver.restore(sess, author)
  File "/home/john/anaconda3/envs/tensorflow/lib/python3.6/site-packages/tensorflow/python/training/saver.py", line 1666, in restore
    {self.saver_def.filename_tensor_name: save_path})
  File "/home/john/anaconda3/envs/tensorflow/lib/python3.6/site-packages/tensorflow/python/client/session.py", line 889, in run
    run_metadata_ptr)
  File "/home/john/anaconda3/envs/tensorflow/lib/python3.6/site-packages/tensorflow/python/client/session.py", line 1120, in _run
    feed_dict_tensor, options, run_metadata)
  File "/home/john/anaconda3/envs/tensorflow/lib/python3.6/site-packages/tensorflow/python/client/session.py", line 1317, in _do_run
    options, run_metadata)
  File "/home/john/anaconda3/envs/tensorflow/lib/python3.6/site-packages/tensorflow/python/client/session.py", line 1336, in _do_call
    raise type(e)(node_def, op, message)
tensorflow.python.framework.errors_impl.OutOfRangeError: Read less bytes than requested
	 [[Node: save/RestoreV2_43 = RestoreV2[dtypes=[DT_FLOAT], _device="/job:localhost/replica:0/task:0/device:CPU:0"](_arg_save/Const_0_0, save/RestoreV2_43/tensor_names, save/RestoreV2_43/shape_and_slices)]]

Caused by op 'save/RestoreV2_43', defined at:
  File "rnn_play.py", line 51, in <module>
    new_saver = tf.train.import_meta_graph('checkpoints/rnn_train_1512567262-0.meta')
  File "/home/john/anaconda3/envs/tensorflow/lib/python3.6/site-packages/tensorflow/python/training/saver.py", line 1810, in import_meta_graph
    **kwargs)
  File "/home/john/anaconda3/envs/tensorflow/lib/python3.6/site-packages/tensorflow/python/framework/meta_graph.py", line 660, in import_scoped_meta_graph
    producer_op_list=producer_op_list)
  File "/home/john/anaconda3/envs/tensorflow/lib/python3.6/site-packages/tensorflow/python/framework/importer.py", line 313, in import_graph_def
    op_def=op_def)
  File "/home/john/anaconda3/envs/tensorflow/lib/python3.6/site-packages/tensorflow/python/framework/ops.py", line 2956, in create_op
    op_def=op_def)
  File "/home/john/anaconda3/envs/tensorflow/lib/python3.6/site-packages/tensorflow/python/framework/ops.py", line 1470, in __init__
    self._traceback = self._graph._extract_stack()  # pylint: disable=protected-access

OutOfRangeError (see above for traceback): Read less bytes than requested
	 [[Node: save/RestoreV2_43 = RestoreV2[dtypes=[DT_FLOAT], _device="/job:localhost/replica:0/task:0/device:CPU:0"](_arg_save/Const_0_0, save/RestoreV2_43/tensor_names, save/RestoreV2_43/shape_and_slices)]]

